Workbook

Sheet Vision Board
B2: GOALS
D6: GYM | G6: CALISTHENICS + GYMNASTICS | J6: GERMAN
D7: - Total Weight: 66 kg | G7: - Handstand | J7: - Goethe Zertifikat C1
D8: - Body Fat: 12% | G8: - Bent Arm Stand
D9: - Visceral Fat: 1% | G9: - HSPU
G10: - Back Handspring
G11: - Backflip
G12: - Tuck Planche
G13: - Tuck Planche Pushup
D16: FRENCH | G16: CAREER DEVELOPMENT | J16: GUITAR
D17: - DELF B2 | G17: - SAA-C03 | J17: - Hangar 18 Cover
G18: - AIF-C01 | J18: - Far Beyond the Sun
G19: - Take IELTS | J19: - Moonlight Sonata (Relearn)
G20: - ROS Course | J20: - 1 Cover per mont
G21: - PLC Course + Possible Certification
G22: - 3 Projects
G23: - AI Courses + Possible Certifications

Sheet Detailed Planning
B4: Language | C4: Current Level | D4: Objective | E4: Daily Intensity [h] | F4: Estimated Time (Best) [months] | G4: Estimated Time (Expected) [months] | H4: Actual Average Daily Intensity [h] | I4: Actual Weekly Intensity [h] | J4: Termination Date (Best) | K4: Termination Date (Expected)
B5: German | C5: B1 | D5: C1 | E5: 3 | F5: 4.5 | G5: 7.5 | H5: =Schedule!J21/7 -> 3 | I5: =Schedule!J21 -> 21 | J5: =EDATE(Logbook!$C$3,'Detailed Planning'!F5) -> 46141 | K5: =EDATE(Logbook!$C$3,'Detailed Planning'!G5) -> 46232
B6: French | C6: B2 | D6: DELF B2 | E6: 1 | F6: 2 | G6: 3 | H6: 1 | I6: 7 | J6: =EDATE(Logbook!$C$3,'Detailed Planning'!F6) -> 46081 | K6: =EDATE(Logbook!$C$3,'Detailed Planning'!G6) -> 46110
B7: English | C7: B2-C1 | D7: IELTS (C1) | E7: 2 | F7: 2.5 | G7: 3.5 | H7: =Schedule!$J$27/7 -> 1.5118571 | I7: =Schedule!$J$27 -> 10.583 | J7: =EDATE(Logbook!$C$3,'Detailed Planning'!F7) -> 46081 | K7: =EDATE(Logbook!$C$3,'Detailed Planning'!G7) -> 46110
B10: Activity | C10: Initial Date | D10: Final Date | E10: Duration (days) | G10: Strategic Time Distribution
B11: SAA-C03 | G11: Task | H11: Condition | I11: Task Priority
B12: Course (remaining) | C12: 46024 | D12: 46029 | E12: =_xlfn.DAYS(D12, C12)+1 -> 6 | G12: To-Do-List | H12: At least one task <= than:
B13: Review Notes | C13: 46037 | D13: 46044 | E13: =_xlfn.DAYS(D13, C13)+1 -> 8 | G13: Career Development | H13: No tasks =
B14: Self-Study | C14: 46045 | D14: 46059 | E14: =_xlfn.DAYS(D14, C14)+1 -> 15
B15: Test | C15: 46060 | D15: 46060 | E15: =_xlfn.DAYS(D15, C15)+1 -> 1
B16: AIF-C01
B17: Course | C17: - | D17: - | E17: =_xlfn.DAYS(D17, C17) -> #VALUE!
B18: Review Notes | C18: - | D18: - | E18: =_xlfn.DAYS(D18, C18) -> #VALUE!
B19: Self-Study | C19: - | D19: - | E19: =_xlfn.DAYS(D19, C19) -> #VALUE!
B20: Test | C20: - | D20: - | E20: =_xlfn.DAYS(D20, C20) -> #VALUE!
B21: Deutsch B2
B22: Main Book | C22: 46024 | D22: 46066 | E22: =_xlfn.DAYS(D22, C22)+1 -> 43
B23: Test Focused Study | C23: 46067 | D23: 46080 | E23: =_xlfn.DAYS(D23, C23)+1 -> 14
B24: Test Simulations | C24: 46081 | D24: 46094 | E24: =_xlfn.DAYS(D24, C24)+1 -> 14
B25: Goethe-Zertifikat-C1
B26: Main Book | C26: 46114 | D26: 46169 | E26: =_xlfn.DAYS(D26, C26)+1 -> 56
B27: Kapitel 1 | C27: 46114 | D27: 46120 | E27: =_xlfn.DAYS(D27, C27)+1 -> 7
B28: Kapitel 2 | C28: 46121 | D28: 46127 | E28: =_xlfn.DAYS(D28, C28)+1 -> 7
B29: Kapitel 3 | C29: 46128 | D29: 46134 | E29: =_xlfn.DAYS(D29, C29)+1 -> 7
B30: Kapitel 4 | C30: 46135 | D30: 46141 | E30: =_xlfn.DAYS(D30, C30)+1 -> 7
B31: Kapitel 5 | C31: 46142 | D31: 46148 | E31: =_xlfn.DAYS(D31, C31)+1 -> 7
B32: Kapitel 6 | C32: 46149 | D32: 46155 | E32: =_xlfn.DAYS(D32, C32)+1 -> 7
B33: Kapitel 7 | C33: 46156 | D33: 46162 | E33: =_xlfn.DAYS(D33, C33)+1 -> 7
B34: Kapitel 8 | C34: 46163 | D34: 46169 | E34: =_xlfn.DAYS(D34, C34)+1 -> 7
B35: Wortschatzbuch | C35: 46114 | D35: 46163 | E35: =_xlfn.DAYS(D35, C35)+1 -> 50
B36: Kapitel 1 | C36: 46114 | D36: 46123 | E36: =_xlfn.DAYS(D36, C36)+1 -> 10
B37: Kapitel 2 | C37: 46124 | D37: 46133 | E37: =_xlfn.DAYS(D37, C37)+1 -> 10
... B47: Test (Option 2) | C47: 46197 | D47: 46197 | E47: =_xlfn.DAYS(D47, C47)+1 -> 1
B48: DELF B2
B49: Review/Reaconditioning | C49: 46024 | D49: 46053 | E49: =_xlfn.DAYS(D49, C49)+1 -> 30
B50: Test Focused Study | C50: 46053 | D50: 46098 | E50: =_xlfn.DAYS(D50, C50)+1 -> 46
B51: Test Inscription (Option 1) | C51: 46041 | D51: 46069 | E51: =_xlfn.DAYS(D51, C51)+1 -> 29
B52: Test (Option 1) | C52: 46100 | D52: 46100 | E52: =_xlfn.DAYS(D52, C52)+1 -> 1
B53: Test Inscription (Option 2) | C53: 46139 | D53: 46165 | E53: =_xlfn.DAYS(D53, C53)+1 -> 27
B54: Test (Option 2) | C54: 46191 | D54: 46191 | E54: =_xlfn.DAYS(D54, C54)+1 -> 1
...

Sheet Schedule
C3: Monday | D3: Tuesday | E3: Wednesday | F3: Thursday | G3: Friday | H3: Saturday | I3: Sunday | J3: Summary
C4: 4:30 Breakfast 5:00 | D4: 4:30 Breakfast 5:00 | E4: 4:30 Breakfast 5:00 | F4: 4:30 Breakfast 5:00 | G4: 4:30 Breakfast 5:00 | H4: 4:30 Breakfast 5:00 | I4: 4:30 Breakfast 5:00
C5: 5:00 Get Ready 5:30 | D5: 5:00 Get Ready 5:30 | E5: 5:00 Get Ready 5:30 | F5: 5:00 Get Ready 5:30 | G5: 5:00 Get Ready 5:30 | H5: 5:00 Get Ready 5:30 | I5: 5:00 Get Ready 5:30
C6: 5:30 Walk Gym 5:50 | D6: 5:30 Take the Bus 6:20 | E6: 5:30 Take the Bus 6:20 | F6: 5:30 Walk Gym 5:50 | G6: 5:30 Walk Gym 5:50 | H6: 5:30 Strategic Time (Career Development) 7:00 | I6: 5:30 German 8:30
C7: 5:50 Get Ready for Gym 5:55 | D7: 6:20 Get Ready for Gym 6:30 | E7: 6:20 Get Ready for Gym 6:30 | F7: 5:50 Get Ready for Gym 5:55 | G7: 5:50 Get Ready for Gym 5:55 | H7: 7:00 Calisthenics 9:00 | I7: 8:30 Get Ready for Kung Fu 9:00
C8: 5:55 Gym 7:30 | D8: 6:30 Gym 7:20 | E8: 6:30 Gym 7:20 | F8: 5:55 Gym 7:30 | G8: 5:55 Gym 7:30 | H8: 9:00 Shower & Get Ready 9:25 | I8: 9:00 Take the Bus 9:30
C9: 7:30 Walk Home 7:50 | D9: 7:20 Get Ready for Work 7:55 | E9: 7:20 Get Ready for Work 7:55 | F9: 7:30 Walk Home 7:50 | G9: 7:30 Walk Home 7:50 | H9: 9:25 German 12:25 | I9: 9:30 Calisthenics 10:30
C10: 7:50 Shower & Get Ready 8:30 | D10: 7:55 Morning Break 8:30 | E10: 7:55 Morning Break 8:30 | F10: 7:50 Shower & Get Ready 8:30 | G10: 7:50 Shower & Get Ready 8:30 | H10: 12:25 Strategic Time 13:00 | I10: 10:30 Kung Fu 12:00
C11: 8:30 German 11:30 | D11: 8:30 German 10:30 | E11: 8:30 German 10:30 | F11: 8:30 German 11:30 | G11: 8:30 German 11:30 | H11: 13:00 Lunch 14:00 | I11: 12:00 Take the Bus 13:00
C12: 11:30 Strategic Time 13:00 | D12: 10:30 Work 13:00 | E12: 10:30 Work 13:00 | F12: 11:30 Strategic Time 13:00 | G12: 11:30 Strategic Time 13:00 | H12: 14:00 Play Guitar 16:00 | I12: 13:00 Lunch 14:00
C13: 13:00 Lunch 14:00 | D13: 13:00 Lunch 14:00 | E13: 13:00 Lunch 14:00 | F13: 13:00 Lunch 14:00 | G13: 13:00 Lunch 14:00 | H13: 16:00 German 17:00 | I13: 14:00 Play Guitar 16:00
C14: 14:00 Work 17:00 | D14: 14:00 Work 17:00 | E14: 14:00 Work 17:00 | F14: 14:00 Work 17:00 | G14: 14:00 Work 17:00 | H14: 17:00 Free Time 18:30 | I14: 16:00 German 17:00
C15: 17:00 Strategic Time 18:30 | D15: 17:00 Leave Office 17:20 | E15: 17:00 Leave Office 17:20 | F15: 17:00 Strategic Time 18:00 | G15: 17:00 Strategic Time 18:30 | H15: 18:30 Dinner 19:00 | I15: 17:00 Free Time 18:30
C16: 18:30 Dinner 19:00 | D16: 17:30 Take the Bus 19:30 | E16: 17:30 Take the Bus 18:30 | F16: 18:00 Get Ready for Kung Fu 18:45 | G16: 18:30 Dinner 19:00 | H16: 19:00 Free Time 21:00 | I16: 18:30 Dinner 19:00
C17: 19:00 Free Time 21:00 | D17: 19:30 Kung Fu 21:00 | E17: 18:30 Unpack & Dinner 19:30 | F17: 18:45 Take the Bus 19:20 | G17: 19:00 Free Time 21:00 | I17: 19:00 Free Time 21:00
D18: 21:00 Take the Bus 22:00 | E18: 19:30 Free Time 21:00 | F18: 19:30 Kung Fu 21:00
D19: 22:00 Dinner & Get Ready to Sleep 22:30 | F19: 21:00 Take the Bus 22:00
F20: 22:00 Dinner & Get Ready to Sleep 22:30
B21: German | C21: =ROUND(3,3)&" (3h)" -> 3 (3h) | D21: =ROUND(2,3)&" (2h)" -> 2 (2h) | E21: =ROUND(2,3)&" (2h)" -> 2 (2h) | F21: =ROUND(3,3)&" (3h)" -> 3 (3h) | G21: =ROUND(3,3)&" (3h)" -> 3 (3h) | H21: =ROUND(4,3)&" (4h)" -> 4 (4h) | I21: =ROUND(4,3)&" (4h)" -> 4 (4h) | J21: =SUM(VALUE(LEFT(C21,FIND(" ",C21)-1)),VALUE(LEFT(D21,FIND(" ",D21)-1)),VALUE(LEFT(E21,FIND(" ",E21)-1)),VALUE(LEFT(F21,FIND(" ",F21)-1)),VALUE(LEFT(G21,FIND(" ",G21)-1)),VALUE(LEFT(H21,FIND(" ",H21)-1)),VALUE(LEFT(I21,FIND(" ",I21)-1))) -> 21 | K21: =ROUNDDOWN(J21,0)&"h"&ROUND((J21-ROUNDDOWN(J21,0))*60,0) -> 21h0
B22: Gym | C22: =ROUND(95/60,3)&" (1h35)" -> 1,583 (1h35) | D22: =ROUND(50/60,3)&" (0h50)" -> 0,833 (0h50) | E22: =ROUND(50/60,3)&" (0h55)" -> 0,833 (0h55) | F22: =ROUND(95/60,3)&" (1h35)" -> 1,583 (1h35) | G22: =ROUND(95/60,3)&" (1h35)" -> 1,583 (1h35) | H22: =ROUND(0,3)&" (0h)" -> 0 (0h) | I22: =ROUND(0,3)&" (0h)" -> 0 (0h) | J22: =SUM(VALUE(LEFT(C22,FIND(" ",C22)-1)),VALUE(LEFT(D22,FIND(" ",D22)-1)),VALUE(LEFT(E22,FIND(" ",E22)-1)),VALUE(LEFT(F22,FIND(" ",F22)-1)),VALUE(LEFT(G22,FIND(" ",G22)-1)),VALUE(LEFT(H22,FIND(" ",H22)-1)),VALUE(LEFT(I22,FIND(" ",I22)-1))) -> 6.415 | K22: =ROUNDDOWN(J22,0)&"h"&ROUND((J22-ROUNDDOWN(J22,0))*60,0) -> 6h25
B23: Work | C23: =ROUND(3,3)&" (3h)" -> 3 (3h) | D23: =ROUND(5.5,3)&" (5h30)" -> 5,5 (5h30) | E23: =ROUND(5.5,3)&" (5h30)" -> 5,5 (5h30) | F23: =ROUND(3,3)&" (3h)" -> 3 (3h) | G23: =ROUND(3,3)&" (3h)" -> 3 (3h) | H23: =ROUND(0,3)&" (0h)" -> 0 (0h) | I23: =ROUND(0,3)&" (0h)" -> 0 (0h) | J23: =SUM(VALUE(LEFT(C23,FIND(" ",C23)-1)),VALUE(LEFT(D23,FIND(" ",D23)-1)),VALUE(LEFT(E23,FIND(" ",E23)-1)),VALUE(LEFT(F23,FIND(" ",F23)-1)),VALUE(LEFT(G23,FIND(" ",G23)-1)),VALUE(LEFT(H23,FIND(" ",H23)-1)),VALUE(LEFT(I23,FIND(" ",I23)-1))) -> 20 | K23: =ROUNDDOWN(J23,0)&"h"&ROUND((J23-ROUNDDOWN(J23,0))*60,0) -> 20h0
B24: Calisthenics | C24: =ROUND(0,3)&" (0h)" -> 0 (0h) | D24: =ROUND(0,3)&" (0h)" -> 0 (0h) | E24: =ROUND(0,3)&" (0h)" -> 0 (0h) | F24: =ROUND(0,3)&" (0h)" -> 0 (0h) | G24: =ROUND(0,3)&" (0h)" -> 0 (0h) | H24: =ROUND(2,3)&" (2h)" -> 2 (2h) | I24: =ROUND(1,3)&" (1h)" -> 1 (1h) | J24: =SUM(VALUE(LEFT(C24,FIND(" ",C24)-1)),VALUE(LEFT(D24,FIND(" ",D24)-1)),VALUE(LEFT(E24,FIND(" ",E24)-1)),VALUE(LEFT(F24,FIND(" ",F24)-1)),VALUE(LEFT(G24,FIND(" ",G24)-1)),VALUE(LEFT(H24,FIND(" ",H24)-1)),VALUE(LEFT(I24,FIND(" ",I24)-1))) -> 3 | K24: =ROUNDDOWN(J24,0)&"h"&ROUND((J24-ROUNDDOWN(J24,0))*60,0) -> 3h0
B25: Kung Fu | C25: =ROUND(0,3)&" (0h)" -> 0 (0h) | D25: =ROUND(2.5,3)&" (2h30)" -> 2,5 (2h30) | E25: =ROUND(0,3)&" (0h)" -> 0 (0h) | F25: =ROUND(2.5,3)&" (2h30)" -> 2,5 (2h30) | G25: =ROUND(0,3)&" (0h)" -> 0 (0h) | H25: =ROUND(0,3)&" (0h)" -> 0 (0h) | I25: =ROUND(1.5,3)&" (1h30)" -> 1,5 (1h30) | J25: =SUM(VALUE(LEFT(C25,FIND(" ",C25)-1)),VALUE(LEFT(D25,FIND(" ",D25)-1)),VALUE(LEFT(E25,FIND(" ",E25)-1)),VALUE(LEFT(F25,FIND(" ",F25)-1)),VALUE(LEFT(G25,FIND(" ",G25)-1)),VALUE(LEFT(H25,FIND(" ",H25)-1)),VALUE(LEFT(I25,FIND(" ",I25)-1))) -> 6.5 | K25: =ROUNDDOWN(J25,0)&"h"&ROUND((J25-ROUNDDOWN(J25,0))*60,0) -> 6h30
B26: Guitar | C26: =ROUND(0,3)&" (0h)" -> 0 (0h) | D26: =ROUND(0,3)&" (0h)" -> 0 (0h) | E26: =ROUND(0,3)&" (0h)" -> 0 (0h) | F26: =ROUND(0,3)&" (0h)" -> 0 (0h) | G26: =ROUND(0,3)&" (0h)" -> 0 (0h) | H26: =ROUND(2,3)&" (2h)" -> 2 (2h) | I26: =ROUND(2,3)&" (2h)" -> 2 (2h) | J26: =SUM(VALUE(LEFT(C26,FIND(" ",C26)-1)),VALUE(LEFT(D26,FIND(" ",D26)-1)),VALUE(LEFT(E26,FIND(" ",E26)-1)),VALUE(LEFT(F26,FIND(" ",F26)-1)),VALUE(LEFT(G26,FIND(" ",G26)-1)),VALUE(LEFT(H26,FIND(" ",H26)-1)),VALUE(LEFT(I26,FIND(" ",I26)-1))) -> 4 | K26: =ROUNDDOWN(J26,0)&"h"&ROUND((J26-ROUNDDOWN(J26,0))*60,0) -> 4h0
B27: Strategic Time | C27: =ROUND(3,3)&" (3h)" -> 3 (3h) | D27: =ROUND(0,3)&" (0h)" -> 0 (0h) | E27: =ROUND(0,3)&" (0h)" -> 0 (0h) | F27: =ROUND(2.5,3)&" (2h30)" -> 2,5 (2h30) | G27: =ROUND(3,3)&" (3h)" -> 3 (3h) | H27: =ROUND(125/60,3)&" (2h5)" -> 2,083 (2h5) | I27: =ROUND(0,3)&" (0h)" -> 0 (0h) | J27: =SUM(VALUE(LEFT(C27,FIND(" ",C27)-1)),VALUE(LEFT(D27,FIND(" ",D27)-1)),VALUE(LEFT(E27,FIND(" ",E27)-1)),VALUE(LEFT(F27,FIND(" ",F27)-1)),VALUE(LEFT(G27,FIND(" ",G27)-1)),VALUE(LEFT(H27,FIND(" ",H27)-1)),VALUE(LEFT(I27,FIND(" ",I27)-1))) -> 10.583 | K27: =ROUNDDOWN(J27,0)&"h"&ROUND((J27-ROUNDDOWN(J27,0))*60,0) -> 10h35
B28: Free Time | C28: =ROUND(2,3)&" (2h)" -> 2 (2h) | D28: =ROUND(0,3)&" (0h)" -> 0 (0h) | E28: =ROUND(1.5,3)&" (1h30)" -> 1,5 (1h30) | F28: =ROUND(0,3)&" (0h)" -> 0 (0h) | G28: =ROUND(2,3)&" (2h)" -> 2 (2h) | H28: =ROUND(3.5,3)&" (3h30)" -> 3,5 (3h30) | I28: =ROUND(3.5,3)&" (3h30)" -> 3,5 (3h30) | J28: =SUM(VALUE(LEFT(C28,FIND(" ",C28)-1)),VALUE(LEFT(D28,FIND(" ",D28)-1)),VALUE(LEFT(E28,FIND(" ",E28)-1)),VALUE(LEFT(F28,FIND(" ",F28)-1)),VALUE(LEFT(G28,FIND(" ",G28)-1)),VALUE(LEFT(H28,FIND(" ",H28)-1)),VALUE(LEFT(I28,FIND(" ",I28)-1))) -> 12.5 | K28: =ROUNDDOWN(J28,0)&"h"&ROUND((J28-ROUNDDOWN(J28,0))*60,0) -> 12h30
B29: Sleep | C29: =ROUND(7.5,3)&" (7h30)" -> 7,5 (7h30) | D29: =ROUND(7.5,3)&" (7h30)" -> 7,5 (7h30) | E29: =ROUND(7.5,3)&" (7h30)" -> 7,5 (7h30) | F29: =ROUND(7.5,3)&" (7h30)" -> 7,5 (7h30) | G29: =ROUND(7.5,3)&" (7h30)" -> 7,5 (7h30) | H29: =ROUND(7.5,3)&" (7h30)" -> 7,5 (7h30) | I29: =ROUND(7.5,3)&" (7h30)" -> 7,5 (7h30) | J29: =SUM(VALUE(LEFT(C29,FIND(" ",C29)-1)),VALUE(LEFT(D29,FIND(" ",D29)-1)),VALUE(LEFT(E29,FIND(" ",E29)-1)),VALUE(LEFT(F29,FIND(" ",F29)-1)),VALUE(LEFT(G29,FIND(" ",G29)-1)),VALUE(LEFT(H29,FIND(" ",H29)-1)),VALUE(LEFT(I29,FIND(" ",I29)-1))) -> 52.5 | K29: =ROUNDDOWN(J29,0)&"h"&ROUND((J29-ROUNDDOWN(J29,0))*60,0) -> 52h30

Sheet Logbook
C2: ="Week "&ROUNDDOWN(C4/7,0)+1 -> Week 1 | J2: ="Week "&ROUNDDOWN(J4/7,0)+1 -> Week 2 | Q2: ="Week "&ROUNDDOWN(Q4/7,0)+1 -> Week 3 | X2: ="Week "&ROUNDDOWN(X4/7,0)+1 -> Week 4 | AE2: ="Week "&ROUNDDOWN(AE4/7,0)+1 -> Week 5 | AL2: ="Week "&ROUNDDOWN(AL4/7,0)+1 -> Week 6 | AS2: ="Week "&ROUNDDOWN(AS4/7,0)+1 -> Week 7 | AZ2: ="Week "&ROUNDDOWN(AZ4/7,0)+1 -> Week 8 | BG2: ="Week "&ROUNDDOWN(BG4/7,0)+1 -> Week 9 | BN2: ="Week "&ROUNDDOWN(BN4/7,0)+1 -> Week 10 | BU2: ="Week "&ROUNDDOWN(BU4/7,0)+1 -> Week 11 | CB2: ="Week "&ROUNDDOWN(CB4/7,0)+1 -> Week 12 | CI2: ="Week "&ROUNDDOWN(CI4/7,0)+1 -> Week 13 | CP2: ="Week "&ROUNDDOWN(CP4/7,0)+1 -> Week 14 | CW2: ="Week "&ROUNDDOWN(CW4/7,0)+1 -> Week 15 | DD2: ="Week "&ROUNDDOWN(DD4/7,0)+1 -> Week 16 | DK2: ="Week "&ROUNDDOWN(DK4/7,0)+1 -> Week 17 | DR2: ="Week "&ROUNDDOWN(DR4/7,0)+1 -> Week 18 | DY2: ="Week "&ROUNDDOWN(DY4/7,0)+1 -> Week 19 | EF2: ="Week "&ROUNDDOWN(EF4/7,0)+1 -> Week 20 | EM2: ="Week "&ROUNDDOWN(EM4/7,0)+1 -> Week 21 | ET2: ="Week "&ROUNDDOWN(ET4/7,0)+1 -> Week 22 | FA2: ="Week "&ROUNDDOWN(FA4/7,0)+1 -> Week 23 | FH2: ="Week "&ROUNDDOWN(FH4/7,0)+1 -> Week 24 | FO2: ="Week "&ROUNDDOWN(FO4/7,0)+1 -> Week 25 | FV2: ="Week "&ROUNDDOWN(FV4/7,0)+1 -> Week 26 | GC2: ="Week "&ROUNDDOWN(GC4/7,0)+1 -> Week 27 | GJ2: ="Week "&ROUNDDOWN(GJ4/7,0)+1 -> Week 28 | GQ2: ="Week "&ROUNDDOWN(GQ4/7,0)+1 -> Week 29 | GX2: ="Week "&ROUNDDOWN(GX4/7,0)+1 -> Week 30 | HE2: ="Week "&ROUNDDOWN(HE4/7,0)+1 -> Week 31 | HL2: ="Week "&ROUNDDOWN(HL4/7,0)+1 -> Week 32 | HS2: ="Week "&ROUNDDOWN(HS4/7,0)+1 -> Week 33 | HZ2: ="Week "&ROUNDDOWN(HZ4/7,0)+1 -> Week 34 | IG2: ="Week "&ROUNDDOWN(IG4/7,0)+1 -> Week 35 | IN2: ="Week "&ROUNDDOWN(IN4/7,0)+1 -> Week 36 | IU2: ="Week "&ROUNDDOWN(IU4/7,0)+1 -> Week 37 | JB2: ="Week "&ROUNDDOWN(JB4/7,0)+1 -> Week 38 | JI2: ="Week "&ROUNDDOWN(JI4/7,0)+1 -> Week 39 | JP2: ="Week "&ROUNDDOWN(JP4/7,0)+1 -> Week 40 | JW2: ="Week "&ROUNDDOWN(JW4/7,0)+1 -> Week 41 | KD2: ="Week "&ROUNDDOWN(KD4/7,0)+1 -> Week 42 | KK2: ="Week "&ROUNDDOWN(KK4/7,0)+1 -> Week 43 | KR2: ="Week "&ROUNDDOWN(KR4/7,0)+1 -> Week 44 | KY2: ="Week "&ROUNDDOWN(KY4/7,0)+1 -> Week 45 | LF2: ="Week "&ROUNDDOWN(LF4/7,0)+1 -> Week 46 | LM2: ="Week "&ROUNDDOWN(LM4/7,0)+1 -> Week 47 | LT2: ="Week "&ROUNDDOWN(LT4/7,0)+1 -> Week 48 | MA2: ="Week "&ROUNDDOWN(MA4/7,0)+1 -> Week 49 | MH2: ="Week "&ROUNDDOWN(MH4/7,0)+1 -> Week 50 | MO2: ="Week "&ROUNDDOWN(MO4/7,0)+1 -> Week 51 | MV2: ="Week "&ROUNDDOWN(MV4/7,0)+1 -> Week 52
C3: 46020 | D3: =C$3+1 -> 46021 | E3: =D$3+1 -> 46022 | F3: =E$3+1 -> 46023 | G3: =F$3+1 -> 46024 | H3: =G$3+1 -> 46025 | I3: =H$3+1 -> 46026 | J3: =I$3+1 -> 46027 | K3: =J$3+1 -> 46028 | ... NC3: =NB$3+1 -> 46384
C4: {=_xlfn.SEQUENCE(,365)} -> 1 | D4: 2 | E4: 3 | F4: 4 | G4: 5 | H4: 6 | I4: 7 | J4: 8 | K4: 9 | L4: 10 | M4: 11 | N4: 12 | O4: 13 | P4: 14 | Q4: 15 | R4: 16 | S4: 17 | T4: 18 | U4: 19 | V4: 20 | W4: 21 | X4: 22 | Y4: 23 | Z4: 24 | AA4: 25 | AB4: 26 | AC4: 27 | AD4: 28 | AE4: 29 | AF4: 30 | AG4: 31 | AH4: 32 | AI4: 33 | AJ4: 34 | AK4: 35 | AL4: 36 | AM4: 37 | AN4: 38 | AO4: 39 | AP4: 40 | AQ4: 41 | AR4: 42 | AS4: 43 | AT4: 44 | AU4: 45 | AV4: 46 | AW4: 47 | AX4: 48 | AY4: 49 | AZ4: 50 | BA4: 51 | BB4: 52 | BC4: 53 | BD4: 54 | BE4: 55 | BF4: 56 | BG4: 57 | BH4: 58 | BI4: 59 | BJ4: 60 | BK4: 61 | BL4: 62 | BM4: 63 | BN4: 64 | BO4: 65 | BP4: 66 | BQ4: 67 | BR4: 68 | BS4: 69 | BT4: 70 | BU4: 71 | BV4: 72 | BW4: 73 | BX4: 74 | BY4: 75 | BZ4: 76 | CA4: 77 | CB4: 78 | CC4: 79 | CD4: 80 | CE4: 81 | CF4: 82 | CG4: 83 | CH4: 84 | CI4: 85 | CJ4: 86 | CK4: 87 | CL4: 88 | CM4: 89 | CN4: 90 | CO4: 91 | CP4: 92 | CQ4: 93 | CR4: 94 | CS4: 95 | CT4: 96 | CU4: 97 | CV4: 98 | CW4: 99 | CX4: 100 | CY4: 101 | CZ4: 102 | DA4: 103 | DB4: 104 | DC4: 105 | DD4: 106 | DE4: 107 | DF4: 108 | DG4: 109 | DH4: 110 | DI4: 111 | DJ4: 112 | DK4: 113 | DL4: 114 | DM4: 115 | DN4: 116 | DO4: 117 | DP4: 118 | DQ4: 119 | DR4: 120 | DS4: 121 | DT4: 122 | DU4: 123 | DV4: 124 | DW4: 125 | DX4: 126 | DY4: 127 | DZ4: 128 | EA4: 129 | EB4: 130 | EC4: 131 | ED4: 132 | EE4: 133 | EF4: 134 | EG4: 135 | EH4: 136 | EI4: 137 | EJ4: 138 | EK4: 139 | EL4: 140 | EM4: 141 | EN4: 142 | EO4: 143 | EP4: 144 | EQ4: 145 | ER4: 146 | ES4: 147 | ET4: 148 | EU4: 149 | EV4: 150 | EW4: 151 | EX4: 152 | EY4: 153 | EZ4: 154 | FA4: 155 | FB4: 156 | FC4: 157 | FD4: 158 | FE4: 159 | FF4: 160 | FG4: 161 | FH4: 162 | FI4: 163 | FJ4: 164 | FK4: 165 | FL4: 166 | FM4: 167 | FN4: 168 | FO4: 169 | FP4: 170 | FQ4: 171 | FR4: 172 | FS4: 173 | FT4: 174 | FU4: 175 | FV4: 176 | FW4: 177 | FX4: 178 | FY4: 179 | FZ4: 180 | GA4: 181 | GB4: 182 | GC4: 183 | GD4: 184 | GE4: 185 | GF4: 186 | GG4: 187 | GH4: 188 | GI4: 189 | GJ4: 190 | GK4: 191 | GL4: 192 | GM4: 193 | GN4: 194 | GO4: 195 | GP4: 196 | GQ4: 197 | GR4: 198 | GS4: 199 | GT4: 200 | GU4: 201 | GV4: 202 | GW4: 203 | GX4: 204 | GY4: 205 | GZ4: 206 | HA4: 207 | HB4: 208 | HC4: 209 | HD4: 210 | HE4: 211 | HF4: 212 | HG4: 213 | HH4: 214 | HI4: 215 | HJ4: 216 | HK4: 217 | HL4: 218 | HM4: 219 | HN4: 220 | HO4: 221 | HP4: 222 | HQ4: 223 | HR4: 224 | HS4: 225 | HT4: 226 | HU4: 227 | HV4: 228 | HW4: 229 | HX4: 230 | HY4: 231 | HZ4: 232 | IA4: 233 | IB4: 234 | IC4: 235 | ID4: 236 | IE4: 237 | IF4: 238 | IG4: 239 | IH4: 240 | II4: 241 | IJ4: 242 | IK4: 243 | IL4: 244 | IM4: 245 | IN4: 246 | IO4: 247 | IP4: 248 | IQ4: 249 | IR4: 250 | IS4: 251 | IT4: 252 | IU4: 253 | IV4: 254 | IW4: 255 | IX4: 256 | IY4: 257 | IZ4: 258 | JA4: 259 | JB4: 260 | JC4: 261 | JD4: 262 | JE4: 263 | JF4: 264 | JG4: 265 | JH4: 266 | JI4: 267 | JJ4: 268 | JK4: 269 | JL4: 270 | JM4: 271 | JN4: 272 | JO4: 273 | JP4: 274 | JQ4: 275 | JR4: 276 | JS4: 277 | JT4: 278 | JU4: 279 | JV4: 280 | JW4: 281 | JX4: 282 | JY4: 283 | JZ4: 284 | KA4: 285 | KB4: 286 | KC4: 287 | KD4: 288 | KE4: 289 | KF4: 290 | KG4: 291 | KH4: 292 | KI4: 293 | KJ4: 294 | KK4: 295 | KL4: 296 | KM4: 297 | KN4: 298 | KO4: 299 | KP4: 300 | KQ4: 301 | KR4: 302 | KS4: 303 | KT4: 304 | KU4: 305 | KV4: 306 | KW4: 307 | KX4: 308 | KY4: 309 | KZ4: 310 | LA4: 311 | LB4: 312 | LC4: 313 | LD4: 314 | LE4: 315 | LF4: 316 | LG4: 317 | LH4: 318 | LI4: 319 | LJ4: 320 | LK4: 321 | LL4: 322 | LM4: 323 | LN4: 324 | LO4: 325 | LP4: 326 | LQ4: 327 | LR4: 328 | LS4: 329 | LT4: 330 | LU4: 331 | LV4: 332 | LW4: 333 | LX4: 334 | LY4: 335 | LZ4: 336 | MA4: 337 | MB4: 338 | MC4: 339 | MD4: 340 | ME4: 341 | MF4: 342 | MG4: 343 | MH4: 344 | MI4: 345 | MJ4: 346 | MK4: 347 | ML4: 348 | MM4: 349 | MN4: 350 | MO4: 351 | MP4: 352 | MQ4: 353 | MR4: 354 | MS4: 355 | MT4: 356 | MU4: 357 | MV4: 358 | MW4: 359 | MX4: 360 | MY4: 361 | MZ4: 362 | NA4: 363 | NB4: 364 | NC4: 365
A5: GYM / CALISTHENICS | B5: Daily Training | C5: Done | D5: Done | E5: Done | F5: Not Scheduled | G5: Done | H5: Done | I5: Not Scheduled | J5: Done | K5: Done | L5: Done | M5: Done | N5: Missed | O5: Done | P5: Missed | Q5: Done | R5: Done | S5: Done | T5: Missed | U5: Not Scheduled | V5: Not Scheduled | W5: Not Scheduled | X5: Not Scheduled | Y5: Not Scheduled | Z5: Not Scheduled | AA5: Not Scheduled | AB5: Missed | AC5: Done | AD5: Not Scheduled | AE5: Done | AF5: Done | AG5: Missed | AH5: Missed | AI5: Done | AJ5: Missed | AK5: Missed | AL5: Done | AM5: Done | AN5: Done | AO5: Missed | AP5: Done | AQ5: Missed | AR5: Not Scheduled | AS5: Missed | AT5: Done | AU5: Done | AV5: Done | AW5: Done | CN5: Done | CO5: Done | CP5: Done | CQ5: Done | CR5: Done | CS5: Not Scheduled | CT5: Not Scheduled | CU5: Not Scheduled | CV5: Done | CW5: Done | CX5: Done | CY5: Not Scheduled | CZ5: Done | DA5: Done | DB5: Done | DC5: Done | DD5: Done | DE5: Done | DF5: Done | DG5: Not Scheduled | DH5: Missed | DI5: Done | DJ5: Missed | DK5: Done | DL5: Not Scheduled | DM5: Not Scheduled | DN5: Done | DO5: Not Scheduled | DP5: Done
A6: STRATEGIC TIME | B6: Planning | C6: Done | D6: Done | E6: Done | F6: Not Scheduled | G6: Not Scheduled | H6: Not Scheduled | I6: Not Scheduled | J6: Missed | K6: Not Scheduled | L6: Done | M6: Not Scheduled | N6: Missed | O6: Missed | P6: Missed | Q6: Done | R6: Not Scheduled | S6: Not Scheduled | T6: Done | U6: Done | V6: Missed | W6: Not Scheduled | X6: Done | Y6: Not Scheduled | Z6: Missed | AA6: Missed | AB6: Missed | AC6: Missed | AD6: Missed | AE6: Not Scheduled | AF6: Not Scheduled | AG6: Not Scheduled | AH6: Missed | AI6: Done | AJ6: Missed | AK6: Missed | AL6: Done | AM6: Not Scheduled | AN6: Not Scheduled | AO6: Done | AP6: Done | AQ6: Done | AR6: Done | AS6: Done | AT6: Not Scheduled | AU6: Done | AV6: Done | AW6: Done | CN6: Done | CO6: Not Scheduled | CP6: Done | CQ6: Not Scheduled | CR6: Not Scheduled | CS6: Not Scheduled | CT6: Not Scheduled | CU6: Not Scheduled | CV6: Missed | CW6: Not Scheduled | CX6: Not Scheduled | CY6: Not Scheduled | CZ6: Not Scheduled | DA6: Not Scheduled | DB6: Not Scheduled | DC6: Not Scheduled | DD6: Not Scheduled | DE6: Not Scheduled | DF6: Not Scheduled | DG6: Missed | DH6: Missed | DI6: Not Scheduled | DJ6: Not Scheduled | DK6: Missed | DL6: Not Scheduled | DM6: Not Scheduled | DN6: Not Scheduled | DO6: Done | DP6: Not Scheduled
B7: Execution | C7: Done | D7: Done | E7: Done | F7: Not Scheduled | G7: Not Scheduled | H7: Not Scheduled | I7: Done | J7: Done | K7: Done | L7: Done | M7: Not Scheduled | N7: Missed | O7: Missed | P7: Missed | Q7: Done | R7: Not Scheduled | S7: Not Scheduled | T7: Done | U7: Done | V7: Missed | W7: Not Scheduled | X7: Not Scheduled | Y7: Not Scheduled | Z7: Missed | AA7: Missed | AB7: Missed | AC7: Missed | AD7: Missed | AE7: Done | AF7: Not Scheduled | AG7: Not Scheduled | AH7: Missed | AI7: Done | AJ7: Missed | AK7: Missed | AL7: Done | AM7: Not Scheduled | AN7: Not Scheduled | AO7: Done | AP7: Not Scheduled | AQ7: Not Scheduled | AR7: Not Scheduled | AS7: Not Scheduled | AT7: Not Scheduled | AU7: Not Scheduled | AV7: Not Scheduled | AW7: Not Scheduled | CN7: Done | CO7: Done | CP7: Done | CQ7: Not Scheduled | CR7: Not Scheduled | CS7: Not Scheduled | CT7: Missed | CU7: Missed | CV7: Not Scheduled | CW7: Done | CX7: Not Scheduled | CY7: Not Scheduled | CZ7: Done | DA7: Done | DB7: Done | DC7: Not Scheduled | DD7: Done | DE7: Not Scheduled | DF7: Not Scheduled | DG7: Missed | DH7: Missed | DI7: Done | DJ7: Not Scheduled | DK7: Missed | DL7: Not Scheduled | DM7: Not Scheduled | DN7: Done | DO7: Done | DP7: Done
A8: GERMAN | B8: Main Study | C8: Done | D8: Done | E8: Not Scheduled | F8: Done | G8: Done | H8: Missed | I8: Missed | J8: Done | K8: Done | L8: Done | M8: Done | N8: Done | O8: Done | P8: Missed | Q8: Done | R8: Done | S8: Done | T8: Missed | U8: Missed | V8: Done | W8: Done | X8: Done | Y8: Done | Z8: Done | AA8: Missed | AB8: Missed | AC8: Missed | AD8: Missed | AE8: Done | AF8: Done | AG8: Done | AH8: Done | AI8: Done | AJ8: Missed | AK8: Missed | AL8: Done | AM8: Done | AN8: Done | AO8: Missed | AP8: Missed | AQ8: Done | AR8: Done | AS8: Done | AT8: Done | AU8: Done | AV8: Done | AW8: Missed | CN8: Missed | CO8: Done | CP8: Done | CQ8: Done | CR8: Done | CS8: Done | CT8: Done | CU8: Done | CV8: Missed | CW8: Done | CX8: Done | CY8: Done | CZ8: Done | DA8: Done | DB8: Done | DC8: Done | DD8: Done | DE8: Done | DF8: Done | DG8: Missed | DH8: Missed | DI8: Missed | DJ8: Done | DK8: Done | DL8: Done | DM8: Done | DN8: Done | DO8: Done | DP8: Done
B9: Flashcards (20 min) | C9: Done | D9: Done | E9: Not Scheduled | F9: Missed | G9: Done | H9: Missed | I9: Missed | J9: Missed | K9: Missed | L9: Missed | M9: Missed | N9: Missed | O9: Missed | P9: Missed | Q9: Missed | R9: Done | S9: Done | T9: Missed | U9: Missed | V9: Missed | W9: Missed | X9: Missed | Y9: Done | Z9: Done | AA9: Missed | AB9: Missed | AC9: Missed | AD9: Missed | AE9: Missed | AF9: Done | AG9: Done | AH9: Missed | AI9: Missed | AJ9: Missed | AK9: Missed | AL9: Missed | AM9: Done | AN9: Done | AO9: Missed | AP9: Missed | AQ9: Missed | AR9: Missed | AS9: Missed | AT9: Done | AU9: Done | AV9: Done | AW9: Missed | CN9: Missed | CO9: Missed | CP9: Done | CQ9: Done | CR9: Done | CS9: Missed | CT9: Missed | CU9: Missed | CV9: Missed | CW9: Done | CX9: Done | CY9: Done | CZ9: Done | DA9: Missed | DB9: Missed | DC9: Missed | DD9: Missed | DE9: Done | DF9: Done | DG9: Done | DH9: Done | DI9: Missed | DJ9: Missed | DK9: Missed | DL9: Done | DM9: Done | DN9: Missed | DO9: Missed | DP9: Missed
A10: NO SCROLLING | B10: NO SCROLLING | CN10: Done | CO10: Done | CP10: Done | CQ10: Done | CR10: Done | CS10: Done | CT10: Missed | CU10: Missed | CV10: Missed | CW10: Done | CX10: Done | CY10: Done | CZ10: Missed | DA10: Missed | DB10: Missed | DC10: Missed | DD10: Missed | DE10: Done | DF10: Missed | DG10: Missed | DH10: Missed | DI10: Missed | DJ10: Done | DK10: Missed | DL10: Missed | DM10: Done | DN10: Done | DO10: Missed | DP10: Done

Sheet To-Do List
B2: Task | C2: Importance (1-5) | D2: Deadline | E2: Progress (1-5) | F2: Priority | G2: Status Description
B3: Certificado de Antigüedad Colmédica | C3: 4 | D3: 46137 | E3: 1 | F3: =C3 + MAX(0, (30-_xlfn.DAYS(D3, TODAY()))) + (10-E3) -> 44
B4: Organize Room (Router) | C4: 3 | D4: 46138 | E4: 3 | F4: =C4 + MAX(0, (30-_xlfn.DAYS(D4, TODAY()))) + (10-E4) -> 40
B5: Redesign CVs | C5: 3 | D5: 46144 | E5: 0 | F5: =C5 + MAX(0, (30-_xlfn.DAYS(D5, TODAY()))) + (10-E5) -> 37
B6: Get DAAD Scholarships Info | C6: 3 | D6: 46144 | E6: 0 | F6: =C6 + MAX(0, (30-_xlfn.DAYS(D6, TODAY()))) + (10-E6) -> 37
B7: Saved Jobs Application LinkedIn | C7: 2 | D7: 46145 | E7: 0 | F7: =C7 + MAX(0, (30-_xlfn.DAYS(D7, TODAY()))) + (10-E7) -> 35
B8: Adjust Meals in Schedule | C8: 3 | D8: 46151 | E8: 0 | F8: =C8 + MAX(0, (30-_xlfn.DAYS(D8, TODAY()))) + (10-E8) -> 30
B9: Stock Investment | C9: 3 | D9: 46151 | E9: 0 | F9: =C9 + MAX(0, (30-_xlfn.DAYS(D9, TODAY()))) + (10-E9) -> 30
B10: Improve Financial Planning by tracking monthly net Earnings | C10: 3 | D10: 46151 | E10: 0 | F10: =C10 + MAX(0, (30-_xlfn.DAYS(D10, TODAY()))) + (10-E10) -> 30
B11: Get info abt Scholarships (Alliance Française) | C11: 2 | D11: 46152 | E11: 0 | F11: =C11 + MAX(0, (30-_xlfn.DAYS(D11, TODAY()))) + (10-E11) -> 28
B12: Improve Goals Planning by graphing total Hours for each activity at the end of the Week | C12: 2 | D12: 46152 | E12: 0 | F12: =C12 + MAX(0, (30-_xlfn.DAYS(D12, TODAY()))) + (10-E12) -> 28
B13: Schedule a Consultation (IMT) | C13: 1 | D13: 46152 | E13: 0 | F13: =C13 + MAX(0, (30-_xlfn.DAYS(D13, TODAY()))) + (10-E13) -> 27
B14: Read Stephan Bey (IMT) | C14: 1 | D14: 46152 | E14: 0 | F14: =C14 + MAX(0, (30-_xlfn.DAYS(D14, TODAY()))) + (10-E14) -> 27
... B24: Pegboard | C24: 1 | D24: 46186 | E24: 0 | F24: =C24 + MAX(0, (30-_xlfn.DAYS(D24, TODAY()))) + (10-E24) -> 11

Sheet Recurrent Tasks Tracker
B2: Name | C2: Frequency | D2: Previous Check | E2: Next Check
B3: Sweep Room | C3: Saturdays | D3: =TODAY()+MOD(6-WEEKDAY(TODAY(),2),7)-7 -> 46137 | E3: =TODAY()+MOD(6-WEEKDAY(TODAY(),2),7) -> 46144
B4: Clean Surfaces | C4: Saturdays | D4: =TODAY()+MOD(6-WEEKDAY(TODAY(),2),7)-7 -> 46137 | E4: =TODAY()+MOD(6-WEEKDAY(TODAY(),2),7) -> 46144
B5: Mop Room | C5: 2 weeks (saturdays) | D5: =$B$1048565+_xlfn.CEILING.MATH((TODAY()-$B$1048565)/14, 1)*14-14 -> 46137 | E5: =$B$1048565+_xlfn.CEILING.MATH((TODAY()-$B$1048565)/14, 1)*14 -> 46151
B6: Cut Nails | C6: 2 weeks (saturdays) | D6: =$B$1048569+_xlfn.CEILING.MATH((TODAY()-$B$1048569)/14, 1)*14-14 -> 46137 | E6: =$B$1048569+_xlfn.CEILING.MATH((TODAY()-$B$1048569)/14, 1)*14 -> 46151
B7: Change Towel | C7: Sundays | D7: =TODAY()+MOD(7-WEEKDAY(TODAY(),2),7)-7 -> 46131 | E7: =TODAY()+MOD(7-WEEKDAY(TODAY(),2),7) -> 46138
B8: Change Pijamas | C8: Sundays | D8: =TODAY()+MOD(7-WEEKDAY(TODAY(),2),7)-7 -> 46131 | E8: =TODAY()+MOD(7-WEEKDAY(TODAY(),2),7) -> 46138
B9: Laundry (underwear) | C9: 5 days | D9: =$B$1048562+_xlfn.CEILING.MATH((TODAY()-$B$1048562)/5, 1)*5-5 -> 46134 | E9: =$B$1048562+_xlfn.CEILING.MATH((TODAY()-$B$1048562)/5, 1)*5 -> 46139
B10: Cash Out | C10: 5th of the month | D10: =IF(DAY(TODAY())>5, DATE(YEAR(TODAY()),MONTH(TODAY()),5), DATE(YEAR(TODAY()),MONTH(TODAY())-1,5)) -> 46117 | E10: =IF(DAY(TODAY())<=5, DATE(YEAR(TODAY()),MONTH(TODAY()),5), DATE(YEAR(TODAY()),MONTH(TODAY())+1,5)) -> 46147
B11: Pay Kung Fu | C11: 5th of the month | D11: =IF(DAY(TODAY())>5, DATE(YEAR(TODAY()),MONTH(TODAY()),5), DATE(YEAR(TODAY()),MONTH(TODAY())-1,5)) -> 46117 | E11: =IF(DAY(TODAY())<=5, DATE(YEAR(TODAY()),MONTH(TODAY()),5), DATE(YEAR(TODAY()),MONTH(TODAY())+1,5)) -> 46147
B12: Recharge Transport Card | C12: 21 days | D12: =$B$1048576+_xlfn.CEILING.MATH((TODAY()-$B$1048576)/21, 1)*21-21 -> 46132 | E12: =$B$1048576+_xlfn.CEILING.MATH((TODAY()-$B$1048576)/21, 1)*21 -> 46153
B13: Measure Stats | C13: 4 weeks (mondays) | D13: =$B$1048571+_xlfn.CEILING.MATH((TODAY()-$B$1048571)/28, 1)*28-28 -> 46125 | E13: =$B$1048571+_xlfn.CEILING.MATH((TODAY()-$B$1048571)/28, 1)*28 -> 46153
B14: Laundry (uniform) | C14: 15th of the month | D14: =IF(DAY(TODAY())>15, DATE(YEAR(TODAY()),MONTH(TODAY()),15), DATE(YEAR(TODAY()),MONTH(TODAY())-1,15)) -> 46127 | E14: =IF(DAY(TODAY())<=15, DATE(YEAR(TODAY()),MONTH(TODAY()),15), DATE(YEAR(TODAY()),MONTH(TODAY())+1,15)) -> 46157
B15: Clean Guitar | C15: 90 days | D15: =$B$1048568+_xlfn.CEILING.MATH((TODAY()-$B$1048568)/90, 1)*90-90 -> 46067 | E15: =$B$1048568+_xlfn.CEILING.MATH((TODAY()-$B$1048568)/90, 1)*90 -> 46157
B16: Haircut | C16: 23th of the month | D16: =IF(DAY(TODAY())>23, DATE(YEAR(TODAY()),MONTH(TODAY()),23), DATE(YEAR(TODAY()),MONTH(TODAY())-1,23)) -> 46135 | E16: =IF(DAY(TODAY())<=23, DATE(YEAR(TODAY()),MONTH(TODAY()),23), DATE(YEAR(TODAY()),MONTH(TODAY())+1,23)) -> 46165
B17: Shave | C17: 40 days | D17: =$B$1048570+_xlfn.CEILING.MATH((TODAY()-$B$1048570)/40, 1)*40-40 -> 46127 | E17: =$B$1048570+_xlfn.CEILING.MATH((TODAY()-$B$1048570)/40, 1)*40 -> 46167
A1048562: Laundry (underwear) | B1048562: 46064
A1048563: Laundry (uniform) | B1048563: 46042
A1048564: Sweep Room | B1048564: -
A1048565: Mop Room | B1048565: 46067
A1048566: Clean Surfaces | B1048566: -
A1048567: Haircut | B1048567: -
A1048568: Clean Guitar | B1048568: 46067
A1048569: Cut Nails | B1048569: 46067
A1048570: Shave | B1048570: 46047
A1048571: Measure Stats | B1048571: 46069
A1048572: Change Towel | B1048572: -
A1048573: Change Pijamas | B1048573: -
A1048574: Cash Out | B1048574: -
A1048575: Pay Kung Fu | B1048575: -
A1048576: Recharge Transport Card | B1048576: 46048

Sheet Calisthenics Routine
B2: Saturday | F2: Sunday
B3: Duration [min] | C3: Block | D3: Description | F3: Duration [min] | G3: Block | H3: Description
B4: 15 | C4: Warm-up | D4: • Wrist prep (circles, fingertip push-ups) • Shoulder mobility (band dislocates, wall slides) • Dynamic core activation (hollow body rocks, arch rocks) • Plyometric prep (jump squats, bounding drills) | F4: 15 | G4: Handstand balance drills | H4: Short freestanding holds, focus on corrections
B5: 60 | C5: Skill Block | D5: • Handstand practice • Wall handstand holds (belly-to-wall, 5×30–60s) • Freestanding attempts (8–10 kick-ups, focus on balance corrections) • Handstand walking or weight shifts (4–5 sets of 5–10s) • Back Handspring drills • Trampoline or mat: back arch-to-hollow snap drills • Backward rolls to stand (confidence in backward motion) • Jump back bridges (strengthen arch position) • Spotted/supervised handspring attempts if possible | F5: 15 | G5: Back Handspring technique | H5: Low-impact drills: backward rolls, jump-backs, arch-to-hollow snaps
B6: 45 | C6: Strength & Conditioning | D6: • Pike push-ups (shoulder strength for handstand stability) • Hollow body holds (core control for both skills) • Explosive jumps (box jumps, tuck jumps) for spring power
B7: 15 | C7: Cool-down | D7: • Bridge holds (shoulder extension, back flexibility) • Pancake stretch (hamstring/hip mobility)

Sheet Vocabulary Tracker
B2: ="Day "&ROUNDDOWN(B3/3,0)+1 -> Day 1 | E2: ="Day "&ROUNDDOWN(E3/3,0)+1 -> Day 2 | H2: ="Day "&ROUNDDOWN(H3/3,0)+1 -> Day 3 | K2: ="Day "&ROUNDDOWN(K3/3,0)+1 -> Day 4 | N2: ="Day "&ROUNDDOWN(N3/3,0)+1 -> Day 5 | Q2: ="Day "&ROUNDDOWN(Q3/3,0)+1 -> Day 6 | T2: ="Day "&ROUNDDOWN(T3/3,0)+1 -> Day 7 | W2: ="Day "&ROUNDDOWN(W3/3,0)+1 -> Day 8 | Z2: ="Day "&ROUNDDOWN(Z3/3,0)+1 -> Day 9 | AC2: ="Day "&ROUNDDOWN(AC3/3,0)+1 -> Day 10 | AF2: ="Day "&ROUNDDOWN(AF3/3,0)+1 -> Day 11 | AI2: ="Day "&ROUNDDOWN(AI3/3,0)+1 -> Day 12 | AL2: ="Day "&ROUNDDOWN(AL3/3,0)+1 -> Day 13 | AO2: ="Day "&ROUNDDOWN(AO3/3,0)+1 -> Day 14 | AR2: ="Day "&ROUNDDOWN(AR3/3,0)+1 -> Day 15 | AU2: ="Day "&ROUNDDOWN(AU3/3,0)+1 -> Day 16 | AX2: ="Day "&ROUNDDOWN(AX3/3,0)+1 -> Day 17 | BA2: ="Day "&ROUNDDOWN(BA3/3,0)+1 -> Day 18 | BD2: ="Day "&ROUNDDOWN(BD3/3,0)+1 -> Day 19 | BG2: ="Day "&ROUNDDOWN(BG3/3,0)+1 -> Day 20 | BJ2: ="Day "&ROUNDDOWN(BJ3/3,0)+1 -> Day 21 | BM2: ="Day "&ROUNDDOWN(BM3/3,0)+1 -> Day 22 | BP2: ="Day "&ROUNDDOWN(BP3/3,0)+1 -> Day 23 | BS2: ="Day "&ROUNDDOWN(BS3/3,0)+1 -> Day 24 | BV2: ="Day "&ROUNDDOWN(BV3/3,0)+1 -> Day 25 | BY2: ="Day "&ROUNDDOWN(BY3/3,0)+1 -> Day 26 | CB2: ="Day "&ROUNDDOWN(CB3/3,0)+1 -> Day 27 | CE2: ="Day "&ROUNDDOWN(CE3/3,0)+1 -> Day 28 | CH2: ="Day "&ROUNDDOWN(CH3/3,0)+1 -> Day 29 | CK2: ="Day "&ROUNDDOWN(CK3/3,0)+1 -> Day 30 | CN2: ="Day "&ROUNDDOWN(CN3/3,0)+1 -> Day 31 | CQ2: ="Day "&ROUNDDOWN(CQ3/3,0)+1 -> Day 32 | CT2: ="Day "&ROUNDDOWN(CT3/3,0)+1 -> Day 33 | CW2: ="Day "&ROUNDDOWN(CW3/3,0)+1 -> Day 34 | CZ2: ="Day "&ROUNDDOWN(CZ3/3,0)+1 -> Day 35 | DC2: ="Day "&ROUNDDOWN(DC3/3,0)+1 -> Day 36
B3: {=_xlfn.SEQUENCE(,365)} -> 1 | C3: 2 | D3: 3 | E3: 4 | F3: 5 | G3: 6 | H3: 7 | I3: 8 | J3: 9 | K3: 10 | L3: 11 | M3: 12 | N3: 13 | O3: 14 | P3: 15 | Q3: 16 | R3: 17 | S3: 18 | T3: 19 | U3: 20 | V3: 21 | W3: 22 | X3: 23 | Y3: 24 | Z3: 25 | AA3: 26 | AB3: 27 | AC3: 28 | AD3: 29 | AE3: 30 | AF3: 31 | AG3: 32 | AH3: 33 | AI3: 34 | AJ3: 35 | AK3: 36 | AL3: 37 | AM3: 38 | AN3: 39 | AO3: 40 | AP3: 41 | AQ3: 42 | AR3: 43 | AS3: 44 | AT3: 45 | AU3: 46 | AV3: 47 | AW3: 48 | AX3: 49 | AY3: 50 | AZ3: 51 | BA3: 52 | BB3: 53 | BC3: 54 | BD3: 55 | BE3: 56 | BF3: 57 | BG3: 58 | BH3: 59 | BI3: 60 | BJ3: 61 | BK3: 62 | BL3: 63 | BM3: 64 | BN3: 65 | BO3: 66 | BP3: 67 | BQ3: 68 | BR3: 69 | BS3: 70 | BT3: 71 | BU3: 72 | BV3: 73 | BW3: 74 | BX3: 75 | BY3: 76 | BZ3: 77 | CA3: 78 | CB3: 79 | CC3: 80 | CD3: 81 | CE3: 82 | CF3: 83 | CG3: 84 | CH3: 85 | CI3: 86 | CJ3: 87 | CK3: 88 | CL3: 89 | CM3: 90 | CN3: 91 | CO3: 92 | CP3: 93 | CQ3: 94 | CR3: 95 | CS3: 96 | CT3: 97 | CU3: 98 | CV3: 99 | CW3: 100 | CX3: 101 | CY3: 102 | CZ3: 103 | DA3: 104 | DB3: 105 | DC3: 106 | DD3: 107 | DE3: 108 | DF3: 109 | DG3: 110 | DH3: 111 | DI3: 112 | DJ3: 113 | DK3: 114 | DL3: 115 | DM3: 116 | DN3: 117 | DO3: 118 | DP3: 119 | DQ3: 120 | DR3: 121 | DS3: 122 | DT3: 123 | DU3: 124 | DV3: 125 | DW3: 126 | DX3: 127 | DY3: 128 | DZ3: 129 | EA3: 130 | EB3: 131 | EC3: 132 | ED3: 133 | EE3: 134 | EF3: 135 | EG3: 136 | EH3: 137 | EI3: 138 | EJ3: 139 | EK3: 140 | EL3: 141 | EM3: 142 | EN3: 143 | EO3: 144 | EP3: 145 | EQ3: 146 | ER3: 147 | ES3: 148 | ET3: 149 | EU3: 150 | EV3: 151 | EW3: 152 | EX3: 153 | EY3: 154 | EZ3: 155 | FA3: 156 | FB3: 157 | FC3: 158 | FD3: 159 | FE3: 160 | FF3: 161 | FG3: 162 | FH3: 163 | FI3: 164 | FJ3: 165 | FK3: 166 | FL3: 167 | FM3: 168 | FN3: 169 | FO3: 170 | FP3: 171 | FQ3: 172 | FR3: 173 | FS3: 174 | FT3: 175 | FU3: 176 | FV3: 177 | FW3: 178 | FX3: 179 | FY3: 180 | FZ3: 181 | GA3: 182 | GB3: 183 | GC3: 184 | GD3: 185 | GE3: 186 | GF3: 187 | GG3: 188 | GH3: 189 | GI3: 190 | GJ3: 191 | GK3: 192 | GL3: 193 | GM3: 194 | GN3: 195 | GO3: 196 | GP3: 197 | GQ3: 198 | GR3: 199 | GS3: 200 | GT3: 201 | GU3: 202 | GV3: 203 | GW3: 204 | GX3: 205 | GY3: 206 | GZ3: 207 | HA3: 208 | HB3: 209 | HC3: 210 | HD3: 211 | HE3: 212 | HF3: 213 | HG3: 214 | HH3: 215 | HI3: 216 | HJ3: 217 | HK3: 218 | HL3: 219 | HM3: 220 | HN3: 221 | HO3: 222 | HP3: 223 | HQ3: 224 | HR3: 225 | HS3: 226 | HT3: 227 | HU3: 228 | HV3: 229 | HW3: 230 | HX3: 231 | HY3: 232 | HZ3: 233 | IA3: 234 | IB3: 235 | IC3: 236 | ID3: 237 | IE3: 238 | IF3: 239 | IG3: 240 | IH3: 241 | II3: 242 | IJ3: 243 | IK3: 244 | IL3: 245 | IM3: 246 | IN3: 247 | IO3: 248 | IP3: 249 | IQ3: 250 | IR3: 251 | IS3: 252 | IT3: 253 | IU3: 254 | IV3: 255 | IW3: 256 | IX3: 257 | IY3: 258 | IZ3: 259 | JA3: 260 | JB3: 261 | JC3: 262 | JD3: 263 | JE3: 264 | JF3: 265 | JG3: 266 | JH3: 267 | JI3: 268 | JJ3: 269 | JK3: 270 | JL3: 271 | JM3: 272 | JN3: 273 | JO3: 274 | JP3: 275 | JQ3: 276 | JR3: 277 | JS3: 278 | JT3: 279 | JU3: 280 | JV3: 281 | JW3: 282 | JX3: 283 | JY3: 284 | JZ3: 285 | KA3: 286 | KB3: 287 | KC3: 288 | KD3: 289 | KE3: 290 | KF3: 291 | KG3: 292 | KH3: 293 | KI3: 294 | KJ3: 295 | KK3: 296 | KL3: 297 | KM3: 298 | KN3: 299 | KO3: 300 | KP3: 301 | KQ3: 302 | KR3: 303 | KS3: 304 | KT3: 305 | KU3: 306 | KV3: 307 | KW3: 308 | KX3: 309 | KY3: 310 | KZ3: 311 | LA3: 312 | LB3: 313 | LC3: 314 | LD3: 315 | LE3: 316 | LF3: 317 | LG3: 318 | LH3: 319 | LI3: 320 | LJ3: 321 | LK3: 322 | LL3: 323 | LM3: 324 | LN3: 325 | LO3: 326 | LP3: 327 | LQ3: 328 | LR3: 329 | LS3: 330 | LT3: 331 | LU3: 332 | LV3: 333 | LW3: 334 | LX3: 335 | LY3: 336 | LZ3: 337 | MA3: 338 | MB3: 339 | MC3: 340 | MD3: 341 | ME3: 342 | MF3: 343 | MG3: 344 | MH3: 345 | MI3: 346 | MJ3: 347 | MK3: 348 | ML3: 349 | MM3: 350 | MN3: 351 | MO3: 352 | MP3: 353 | MQ3: 354 | MR3: 355 | MS3: 356 | MT3: 357 | MU3: 358 | MV3: 359 | MW3: 360 | MX3: 361 | MY3: 362 | MZ3: 363 | NA3: 364 | NB3: 365
B4: Session | C4: Cards | D4: Time | E4: Session | F4: Cards | G4: Time | H4: Session | I4: Cards | J4: Time | K4: Session | L4: Cards | M4: Time
B5: 1 | C5: 30 | D5: 25
B6: 2 | C6: 30 | D6: 25
B7: 3
B8: 4
B9: 5
